<?xml version="1.0" ?>
<!-- =================================================================================== -->
<!-- |    This document was autogenerated by xacro from /home/jetson/jetbot_ros/urdf/jetbot.urdf.xacro | -->
<!-- |    EDITING THIS FILE BY HAND IS NOT RECOMMENDED                                 | -->
<!-- =================================================================================== -->
<robot name="jetbot">
  <material name="blue">
    <color rgba="0.2 0.4 0.8 1"/>
  </material>
  <material name="black">
    <color rgba="0.1 0.1 0.1 1"/>
  </material>
  <material name="red">
    <color rgba="1 0 0 0.8"/>
  </material>
  <material name="green">
    <color rgba="0 1 0 0.8"/>
  </material>
  <material name="gray">
    <color rgba="0.5 0.5 0.5 1"/>
  </material>
  <material name="silver">
    <color rgba="0.7 0.7 0.7 1"/>
  </material>
  <link name="base_footprint"/>
  <joint name="base_footprint_joint" type="fixed">
    <parent link="base_footprint"/>
    <child link="body_link"/>
    <origin rpy="0 0 0" xyz="0 0 0.0325"/>
  </joint>
  <link name="body_link">
    <visual>
      <geometry>
        <box size="0.2 0.15 0.005"/>
      </geometry>
      <origin rpy="0 0 0" xyz="0 0 0"/>
      <material name="blue"/>
    </visual>
    <collision>
      <geometry>
        <box size="0.2 0.15 0.005"/>
      </geometry>
      <origin rpy="0 0 0" xyz="0 0 0"/>
    </collision>
    <inertial>
      <origin rpy="0 0 0" xyz="0 0 0"/>
      <mass value="0.075"/>
      <inertia ixx="0.00014078124999999998" ixy="0" ixz="0" iyy="0.00025015625" iyz="0" izz="0.00039062499999999997"/>
    </inertial>
  </link>
  <joint name="base_link_joint" type="fixed">
    <parent link="body_link"/>
    <child link="base_link"/>
    <origin rpy="0 0 0" xyz="0 0 0"/>
  </joint>
  <link name="base_link"/>
  <!-- 左輪：X=+0.05, Y=+0.0875 -->
  <joint name="left_wheel_joint" type="continuous">
    <parent link="body_link"/>
    <child link="left_wheel_link"/>
    <origin rpy="0 0 0" xyz="0.05 0.0875 -0.0025"/>
    <axis xyz="0 1 0"/>
    <limit effort="1000" velocity="1000"/>
    <dynamics damping="1.0" friction="1.0"/>
  </joint>
  <link name="left_wheel_link">
    <visual>
      <origin rpy="1.5708 0 0" xyz="0 0 0"/>
      <geometry>
        <cylinder length="0.025" radius="0.0325"/>
      </geometry>
      <material name="black"/>
    </visual>
    <collision>
      <origin rpy="1.5708 0 0" xyz="0 0 0"/>
      <geometry>
        <cylinder length="0.025" radius="0.0325"/>
      </geometry>
    </collision>
    <inertial>
      <origin rpy="0 0 0" xyz="0 0 0"/>
      <mass value="0.08295768091406253"/>
      <inertia ixx="2.622672516397706e-05" ixy="0.0" ixz="0.0" iyy="2.622672516397706e-05" iyz="0" izz="4.381202523273927e-05"/>
    </inertial>
  </link>
  <!-- 右輪：X=+0.05, Y=-0.0875 -->
  <joint name="right_wheel_joint" type="continuous">
    <parent link="body_link"/>
    <child link="right_wheel_link"/>
    <origin rpy="0 0 0" xyz="0.05 -0.0875 -0.0025"/>
    <axis xyz="0 1 0"/>
    <limit effort="1000" velocity="1000"/>
    <dynamics damping="1.0" friction="1.0"/>
  </joint>
  <link name="right_wheel_link">
    <visual>
      <origin rpy="1.5708 0 0" xyz="0 0 0"/>
      <geometry>
        <cylinder length="0.025" radius="0.0325"/>
      </geometry>
      <material name="black"/>
    </visual>
    <collision>
      <origin rpy="1.5708 0 0" xyz="0 0 0"/>
      <geometry>
        <cylinder length="0.025" radius="0.0325"/>
      </geometry>
    </collision>
    <inertial>
      <origin rpy="0 0 0" xyz="0 0 0"/>
      <mass value="0.08295768091406253"/>
      <inertia ixx="2.622672516397706e-05" ixy="0.0" ixz="0.0" iyy="2.622672516397706e-05" iyz="0" izz="4.381202523273927e-05"/>
    </inertial>
  </link>
  <joint name="caster_joint" type="fixed">
    <parent link="body_link"/>
    <child link="caster_link"/>
    <origin rpy="0 0 0" xyz="-0.08 0 -0.025"/>
  </joint>
  <link name="caster_link">
    <visual>
      <origin rpy="0 0 0" xyz="0 0 0"/>
      <geometry>
        <sphere radius="0.01"/>
      </geometry>
      <material name="silver"/>
    </visual>
    <collision>
      <origin rpy="0 0 0" xyz="0 0 0"/>
      <geometry>
        <sphere radius="0.01"/>
      </geometry>
    </collision>
    <inertial>
      <origin rpy="0 0 0" xyz="0 0 0"/>
      <mass value="0.0041887902000000005"/>
      <inertia ixx="1.6755160800000002e-07" ixy="0.0" ixz="0.0" iyy="1.6755160800000002e-07" iyz="0" izz="1.6755160800000002e-07"/>
    </inertial>
  </link>
  <joint name="camera_pole_joint" type="fixed">
    <parent link="body_link"/>
    <child link="camera_pole_link"/>
    <origin rpy="0 0 0" xyz="0.095 0 0.0025"/>
  </joint>
  <link name="camera_pole_link">
    <visual>
      <origin rpy="0 0 0" xyz="0 0 0.0775"/>
      <geometry>
        <cylinder length="0.155" radius="0.005"/>
      </geometry>
      <material name="gray"/>
    </visual>
  </link>
  <joint name="camera_mount_joint" type="fixed">
    <parent link="camera_pole_link"/>
    <child link="camera_mount_link"/>
    <origin rpy="0 0 0" xyz="0 0 0.155"/>
  </joint>
  <link name="camera_mount_link">
    <visual>
      <geometry>
        <box size="0.01 0.17 0.01"/>
      </geometry>
      <material name="gray"/>
    </visual>
  </link>
  <joint name="camera_left_joint" type="fixed">
    <parent link="camera_mount_link"/>
    <child link="camera_left_link"/>
    <origin rpy="0 0 0" xyz="0 0.08 0"/>
  </joint>
  <link name="camera_left_link">
    <visual>
      <geometry>
        <cylinder length="0.01" radius="0.0025"/>
      </geometry>
      <origin rpy="0 0 0" xyz="0 0 0"/>
      <material name="red"/>
    </visual>
  </link>
  <joint name="camera_left_optical_joint" type="fixed">
    <parent link="camera_left_link"/>
    <child link="camera_left_optical_frame"/>
    <origin rpy="-1.5708 0 -1.5708" xyz="0 0 0"/>
  </joint>
  <link name="camera_left_optical_frame"/>
  <joint name="camera_right_joint" type="fixed">
    <parent link="camera_mount_link"/>
    <child link="camera_right_link"/>
    <origin rpy="0 0 0" xyz="0 -0.08 0"/>
  </joint>
  <link name="camera_right_link">
    <visual>
      <geometry>
        <cylinder length="0.01" radius="0.0025"/>
      </geometry>
      <origin rpy="0 0 0" xyz="0 0 0"/>
      <material name="green"/>
    </visual>
  </link>
  <joint name="camera_right_optical_joint" type="fixed">
    <parent link="camera_right_link"/>
    <child link="camera_right_optical_frame"/>
    <origin rpy="-1.5708 0 -1.5708" xyz="0 0 0"/>
  </joint>
  <link name="camera_right_optical_frame"/>
</robot>
